ERROR - 2025-02-11 16:31:21,748 - readyaml.py:35 -[readyaml:get_testcase_yaml] - [./testcase/UserManager/UserInfo.yaml]文件未找到，请检查路径是否正确
ERROR - 2025-02-11 17:07:16,618 - readyaml.py:35 -[readyaml:get_testcase_yaml] - [./testcase/UserManager/UserInfo.yml]文件未找到，请检查路径是否正确
ERROR - 2025-02-11 17:42:57,782 - readyaml.py:30 -[readyaml:get_testcase_yaml] - 获取【./testcase/UserManager/UserInfo.yml】文件数据时出现未知错误: while parsing a block collection
  in "./testcase/UserManager/UserInfo.yml", line 1, column 1
expected <block end>, but found '?'
  in "./testcase/UserManager/UserInfo.yml", line 7, column 1
ERROR - 2025-02-11 17:43:17,938 - readyaml.py:30 -[readyaml:get_testcase_yaml] - 获取【./testcase/UserManager/UserInfo.yml】文件数据时出现未知错误: while parsing a block collection
  in "./testcase/UserManager/UserInfo.yml", line 1, column 1
expected <block end>, but found '?'
  in "./testcase/UserManager/UserInfo.yml", line 7, column 1
